2017-01-14 20:28:22,151	File "iostream.py",line 557	ERROR: Uncaught exception, closing connection.
Traceback (most recent call last):
  File "/usr/local/lib/python3.5/dist-packages/tornado/iostream.py", line 554, in wrapper
    return callback(*args)
  File "/usr/local/lib/python3.5/dist-packages/tornado/stack_context.py", line 275, in null_wrapper
    return fn(*args, **kwargs)
  File "server.py", line 97, in start_receive_image_data
    self.stream.read_bytes(num_bytes = self.json_request['size'], callback=stack_context.wrap(self.on_image_upload_complete), partial=False)
KeyError: 'size'
2017-01-14 20:28:22,152	File "ioloop.py",line 633	ERROR: Exception in callback functools.partial(<function wrap.<locals>.null_wrapper at 0x7f2e3ca961e0>)
Traceback (most recent call last):
  File "/usr/local/lib/python3.5/dist-packages/tornado/ioloop.py", line 604, in _run_callback
    ret = callback()
  File "/usr/local/lib/python3.5/dist-packages/tornado/stack_context.py", line 275, in null_wrapper
    return fn(*args, **kwargs)
  File "/usr/local/lib/python3.5/dist-packages/tornado/iostream.py", line 554, in wrapper
    return callback(*args)
  File "/usr/local/lib/python3.5/dist-packages/tornado/stack_context.py", line 275, in null_wrapper
    return fn(*args, **kwargs)
  File "server.py", line 97, in start_receive_image_data
    self.stream.read_bytes(num_bytes = self.json_request['size'], callback=stack_context.wrap(self.on_image_upload_complete), partial=False)
KeyError: 'size'
2017-01-14 20:28:22,152	File "server.py",line 132	INFO: 127.0.0.1:52814: disconnect
2017-01-14 20:30:38,132	File "iostream.py",line 557	ERROR: Uncaught exception, closing connection.
Traceback (most recent call last):
  File "/usr/local/lib/python3.5/dist-packages/tornado/iostream.py", line 554, in wrapper
    return callback(*args)
  File "/usr/local/lib/python3.5/dist-packages/tornado/stack_context.py", line 275, in null_wrapper
    return fn(*args, **kwargs)
  File "server.py", line 97, in start_receive_image_data
    self.stream.read_bytes(num_bytes = self.json_request['size'], callback=stack_context.wrap(self.on_image_upload_complete), partial=False)
KeyError: 'size'
2017-01-14 20:30:38,133	File "ioloop.py",line 633	ERROR: Exception in callback functools.partial(<function wrap.<locals>.null_wrapper at 0x7f2e3c62f598>)
Traceback (most recent call last):
  File "/usr/local/lib/python3.5/dist-packages/tornado/ioloop.py", line 604, in _run_callback
    ret = callback()
  File "/usr/local/lib/python3.5/dist-packages/tornado/stack_context.py", line 275, in null_wrapper
    return fn(*args, **kwargs)
  File "/usr/local/lib/python3.5/dist-packages/tornado/iostream.py", line 554, in wrapper
    return callback(*args)
  File "/usr/local/lib/python3.5/dist-packages/tornado/stack_context.py", line 275, in null_wrapper
    return fn(*args, **kwargs)
  File "server.py", line 97, in start_receive_image_data
    self.stream.read_bytes(num_bytes = self.json_request['size'], callback=stack_context.wrap(self.on_image_upload_complete), partial=False)
KeyError: 'size'
2017-01-14 20:30:38,133	File "server.py",line 132	INFO: 127.0.0.1:52828: disconnect
2017-01-14 20:30:57,817	File "iostream.py",line 557	ERROR: Uncaught exception, closing connection.
Traceback (most recent call last):
  File "/usr/local/lib/python3.5/dist-packages/tornado/iostream.py", line 554, in wrapper
    return callback(*args)
  File "/usr/local/lib/python3.5/dist-packages/tornado/stack_context.py", line 275, in null_wrapper
    return fn(*args, **kwargs)
  File "server.py", line 97, in start_receive_image_data
    self.stream.read_bytes(num_bytes = self.json_request['size'], callback=stack_context.wrap(self.on_image_upload_complete), partial=False)
KeyError: 'size'
2017-01-14 20:30:57,818	File "ioloop.py",line 633	ERROR: Exception in callback functools.partial(<function wrap.<locals>.null_wrapper at 0x7fa610c821e0>)
Traceback (most recent call last):
  File "/usr/local/lib/python3.5/dist-packages/tornado/ioloop.py", line 604, in _run_callback
    ret = callback()
  File "/usr/local/lib/python3.5/dist-packages/tornado/stack_context.py", line 275, in null_wrapper
    return fn(*args, **kwargs)
  File "/usr/local/lib/python3.5/dist-packages/tornado/iostream.py", line 554, in wrapper
    return callback(*args)
  File "/usr/local/lib/python3.5/dist-packages/tornado/stack_context.py", line 275, in null_wrapper
    return fn(*args, **kwargs)
  File "server.py", line 97, in start_receive_image_data
    self.stream.read_bytes(num_bytes = self.json_request['size'], callback=stack_context.wrap(self.on_image_upload_complete), partial=False)
KeyError: 'size'
2017-01-14 20:30:57,819	File "server.py",line 132	INFO: 127.0.0.1:52832: disconnect
2017-01-14 20:32:42,786	File "iostream.py",line 557	ERROR: Uncaught exception, closing connection.
Traceback (most recent call last):
  File "/usr/local/lib/python3.5/dist-packages/tornado/iostream.py", line 554, in wrapper
    return callback(*args)
  File "/usr/local/lib/python3.5/dist-packages/tornado/stack_context.py", line 275, in null_wrapper
    return fn(*args, **kwargs)
  File "server.py", line 98, in start_receive_image_data
    self.stream.read_bytes(num_bytes = self.json_request['size'], callback=stack_context.wrap(self.on_image_upload_complete), partial=False)
KeyError: 'size'
2017-01-14 20:32:42,786	File "ioloop.py",line 633	ERROR: Exception in callback functools.partial(<function wrap.<locals>.null_wrapper at 0x7f218fadb1e0>)
Traceback (most recent call last):
  File "/usr/local/lib/python3.5/dist-packages/tornado/ioloop.py", line 604, in _run_callback
    ret = callback()
  File "/usr/local/lib/python3.5/dist-packages/tornado/stack_context.py", line 275, in null_wrapper
    return fn(*args, **kwargs)
  File "/usr/local/lib/python3.5/dist-packages/tornado/iostream.py", line 554, in wrapper
    return callback(*args)
  File "/usr/local/lib/python3.5/dist-packages/tornado/stack_context.py", line 275, in null_wrapper
    return fn(*args, **kwargs)
  File "server.py", line 98, in start_receive_image_data
    self.stream.read_bytes(num_bytes = self.json_request['size'], callback=stack_context.wrap(self.on_image_upload_complete), partial=False)
KeyError: 'size'
2017-01-14 20:32:42,787	File "server.py",line 133	INFO: 127.0.0.1:52842: disconnect
2017-01-14 20:34:57,674	File "iostream.py",line 557	ERROR: Uncaught exception, closing connection.
Traceback (most recent call last):
  File "/usr/local/lib/python3.5/dist-packages/tornado/iostream.py", line 554, in wrapper
    return callback(*args)
  File "/usr/local/lib/python3.5/dist-packages/tornado/stack_context.py", line 275, in null_wrapper
    return fn(*args, **kwargs)
  File "server.py", line 98, in start_receive_image_data
    self.stream.read_bytes(num_bytes = self.json_request['size'], callback=stack_context.wrap(self.on_image_upload_complete), partial=False)
KeyError: 'size'
2017-01-14 20:34:57,675	File "ioloop.py",line 633	ERROR: Exception in callback functools.partial(<function wrap.<locals>.null_wrapper at 0x7ff65de651e0>)
Traceback (most recent call last):
  File "/usr/local/lib/python3.5/dist-packages/tornado/ioloop.py", line 604, in _run_callback
    ret = callback()
  File "/usr/local/lib/python3.5/dist-packages/tornado/stack_context.py", line 275, in null_wrapper
    return fn(*args, **kwargs)
  File "/usr/local/lib/python3.5/dist-packages/tornado/iostream.py", line 554, in wrapper
    return callback(*args)
  File "/usr/local/lib/python3.5/dist-packages/tornado/stack_context.py", line 275, in null_wrapper
    return fn(*args, **kwargs)
  File "server.py", line 98, in start_receive_image_data
    self.stream.read_bytes(num_bytes = self.json_request['size'], callback=stack_context.wrap(self.on_image_upload_complete), partial=False)
KeyError: 'size'
2017-01-14 20:34:57,675	File "server.py",line 133	INFO: 127.0.0.1:52856: disconnect
2017-01-14 20:35:50,402	File "iostream.py",line 557	ERROR: Uncaught exception, closing connection.
Traceback (most recent call last):
  File "/usr/local/lib/python3.5/dist-packages/tornado/iostream.py", line 554, in wrapper
    return callback(*args)
  File "/usr/local/lib/python3.5/dist-packages/tornado/stack_context.py", line 275, in null_wrapper
    return fn(*args, **kwargs)
  File "server.py", line 98, in start_receive_image_data
    self.stream.read_bytes(num_bytes = self.json_request['size'], callback=stack_context.wrap(self.on_image_upload_complete), partial=False)
KeyError: 'size'
2017-01-14 20:35:50,402	File "ioloop.py",line 633	ERROR: Exception in callback functools.partial(<function wrap.<locals>.null_wrapper at 0x7ff65d9fe598>)
Traceback (most recent call last):
  File "/usr/local/lib/python3.5/dist-packages/tornado/ioloop.py", line 604, in _run_callback
    ret = callback()
  File "/usr/local/lib/python3.5/dist-packages/tornado/stack_context.py", line 275, in null_wrapper
    return fn(*args, **kwargs)
  File "/usr/local/lib/python3.5/dist-packages/tornado/iostream.py", line 554, in wrapper
    return callback(*args)
  File "/usr/local/lib/python3.5/dist-packages/tornado/stack_context.py", line 275, in null_wrapper
    return fn(*args, **kwargs)
  File "server.py", line 98, in start_receive_image_data
    self.stream.read_bytes(num_bytes = self.json_request['size'], callback=stack_context.wrap(self.on_image_upload_complete), partial=False)
KeyError: 'size'
2017-01-14 20:35:50,415	File "server.py",line 133	INFO: 127.0.0.1:52858: disconnect
2017-01-14 20:35:58,645	File "iostream.py",line 557	ERROR: Uncaught exception, closing connection.
Traceback (most recent call last):
  File "/usr/local/lib/python3.5/dist-packages/tornado/iostream.py", line 554, in wrapper
    return callback(*args)
  File "/usr/local/lib/python3.5/dist-packages/tornado/stack_context.py", line 275, in null_wrapper
    return fn(*args, **kwargs)
  File "server.py", line 98, in start_receive_image_data
    self.stream.read_bytes(num_bytes = self.json_request['size'], callback=stack_context.wrap(self.on_image_upload_complete), partial=False)
KeyError: 'size'
2017-01-14 20:35:58,645	File "ioloop.py",line 633	ERROR: Exception in callback functools.partial(<function wrap.<locals>.null_wrapper at 0x7f9bb6ccc1e0>)
Traceback (most recent call last):
  File "/usr/local/lib/python3.5/dist-packages/tornado/ioloop.py", line 604, in _run_callback
    ret = callback()
  File "/usr/local/lib/python3.5/dist-packages/tornado/stack_context.py", line 275, in null_wrapper
    return fn(*args, **kwargs)
  File "/usr/local/lib/python3.5/dist-packages/tornado/iostream.py", line 554, in wrapper
    return callback(*args)
  File "/usr/local/lib/python3.5/dist-packages/tornado/stack_context.py", line 275, in null_wrapper
    return fn(*args, **kwargs)
  File "server.py", line 98, in start_receive_image_data
    self.stream.read_bytes(num_bytes = self.json_request['size'], callback=stack_context.wrap(self.on_image_upload_complete), partial=False)
KeyError: 'size'
2017-01-14 20:35:58,646	File "server.py",line 133	INFO: 127.0.0.1:52860: disconnect
2017-01-14 20:39:41,851	File "server.py",line 133	INFO: 127.0.0.1:52904: disconnect
2017-01-14 20:40:08,306	File "server.py",line 133	INFO: 127.0.0.1:52906: disconnect
2017-01-14 20:40:09,490	File "server.py",line 133	INFO: 127.0.0.1:52908: disconnect
2017-01-14 21:22:40,994	File "server.py",line 132	INFO: 127.0.0.1:53510: disconnect
2017-01-14 21:25:15,262	File "server.py",line 132	INFO: 127.0.0.1:53582: disconnect
2017-01-14 21:26:50,797	File "server.py",line 132	INFO: 127.0.0.1:53610: disconnect
2017-01-14 21:33:27,891	File "server.py",line 132	INFO: 127.0.0.1:53630: disconnect
2017-01-14 21:36:42,034	File "server.py",line 132	INFO: 127.0.0.1:53670: disconnect
2017-01-14 21:37:34,883	File "server.py",line 133	INFO: 127.0.0.1:53676: disconnect
2017-01-14 21:39:28,253	File "server.py",line 133	INFO: 127.0.0.1:53704: disconnect
2017-01-14 21:40:29,552	File "server.py",line 134	INFO: 127.0.0.1:53706: disconnect
2017-01-14 21:41:21,413	File "server.py",line 134	INFO: 127.0.0.1:53708: disconnect
2017-01-14 21:42:17,259	File "server.py",line 135	INFO: 127.0.0.1:53710: disconnect
2017-01-14 21:43:04,678	File "server.py",line 135	INFO: 127.0.0.1:53714: disconnect
2017-01-14 21:45:18,541	File "server.py",line 135	INFO: 127.0.0.1:53732: disconnect
2017-01-14 21:45:46,806	File "server.py",line 135	INFO: 127.0.0.1:53736: disconnect
2017-01-14 21:46:42,285	File "server.py",line 135	INFO: 127.0.0.1:53766: disconnect
2017-01-14 21:48:23,211	File "server.py",line 135	INFO: 127.0.0.1:53778: disconnect
2017-01-14 21:57:42,898	File "server.py",line 135	INFO: 127.0.0.1:53854: disconnect
2017-01-14 21:57:49,425	File "server.py",line 135	INFO: 127.0.0.1:53864: disconnect
2017-01-14 21:57:53,629	File "server.py",line 135	INFO: 127.0.0.1:53874: disconnect
2017-01-14 21:57:54,878	File "server.py",line 135	INFO: 127.0.0.1:53884: disconnect
2017-01-14 21:57:55,770	File "server.py",line 135	INFO: 127.0.0.1:53894: disconnect
2017-01-14 21:57:56,718	File "server.py",line 135	INFO: 127.0.0.1:53904: disconnect
2017-01-14 21:57:57,522	File "server.py",line 135	INFO: 127.0.0.1:53914: disconnect
2017-01-14 21:57:58,259	File "server.py",line 135	INFO: 127.0.0.1:53924: disconnect
2017-01-14 21:57:59,006	File "server.py",line 135	INFO: 127.0.0.1:53932: disconnect
2017-01-14 21:57:59,802	File "server.py",line 135	INFO: 127.0.0.1:53940: disconnect
2017-01-14 21:58:00,553	File "server.py",line 135	INFO: 127.0.0.1:53946: disconnect
2017-01-14 21:58:01,270	File "server.py",line 135	INFO: 127.0.0.1:53954: disconnect
2017-01-14 21:58:01,954	File "server.py",line 135	INFO: 127.0.0.1:53960: disconnect
2017-01-14 21:58:02,812	File "server.py",line 135	INFO: 127.0.0.1:53966: disconnect
2017-01-14 21:58:03,518	File "server.py",line 135	INFO: 127.0.0.1:53972: disconnect
2017-01-14 21:58:20,402	File "server.py",line 135	INFO: 127.0.0.1:54006: disconnect
2017-01-14 21:58:22,142	File "server.py",line 135	INFO: 127.0.0.1:54016: disconnect
2017-01-14 21:58:22,793	File "server.py",line 135	INFO: 127.0.0.1:54026: disconnect
2017-01-14 21:58:23,403	File "server.py",line 135	INFO: 127.0.0.1:54034: disconnect
2017-01-14 21:58:24,027	File "server.py",line 135	INFO: 127.0.0.1:54042: disconnect
2017-01-14 21:58:25,010	File "server.py",line 135	INFO: 127.0.0.1:54052: disconnect
2017-01-14 21:58:25,588	File "server.py",line 135	INFO: 127.0.0.1:54060: disconnect
2017-01-14 21:58:26,134	File "server.py",line 135	INFO: 127.0.0.1:54068: disconnect
2017-01-14 21:58:26,891	File "server.py",line 135	INFO: 127.0.0.1:54078: disconnect
2017-01-14 21:58:27,424	File "server.py",line 135	INFO: 127.0.0.1:54086: disconnect
2017-01-14 21:58:28,076	File "server.py",line 135	INFO: 127.0.0.1:54094: disconnect
2017-01-14 21:58:28,697	File "server.py",line 135	INFO: 127.0.0.1:54102: disconnect
2017-01-14 21:58:29,317	File "server.py",line 135	INFO: 127.0.0.1:54112: disconnect
2017-01-14 21:58:29,838	File "server.py",line 135	INFO: 127.0.0.1:54118: disconnect
2017-01-14 21:58:30,442	File "server.py",line 135	INFO: 127.0.0.1:54128: disconnect
2017-01-14 21:58:31,196	File "server.py",line 135	INFO: 127.0.0.1:54136: disconnect
